Workbook

Sheet Risk Mgmt
A1: DBA4014 | C1: Risk Management Rules
A3: Company | B3: DBA4
A4: Date | B4: 46304 | D4: =IF(WEEKDAY(B4)=1,"SUN",IF(WEEKDAY(B4)=2,"MON",IF(WEEKDAY(B4)=3,"TUE",IF(WEEKDAY(B4)=4,"WED",IF(WEEKDAY(B4)=5,"THU",IF(WEEKDAY(B4)=6,"FRI",IF(WEEKDAY(B4)=7,"SAT","-"))))))) -> FRI
A5: Risk Management Rules (Self-Regulation)
A7: Loss-cut | B7: 10 | C7: % Enforcing this rule is primarily the CRO's responsibility. | N7: Our PaperTrade is limited to macro risks only - ETFs, ETNs, (i.e. ETPs) - Futures on indices and commodities - Options on indices and commodities - No investment in individual stocks No single-stock futures No single-stock options + No single-stock ETFs such as: (including but not limited to...) TSLQ: -1× the daily performance of Tesla NVDS: -1.25× the daily performance of Nvidia PYPS: -1.5× the daily performance of PayPal PYPT: +1.5× the daily performance of PayPal NKEQ: -2× the daily performance of Nike NKEL: +2× the daily performance of Nike PFES: -2× the daily performance of Pfizer PFEL: +2× the daily performance of Pfizer
A9: Profit-taking | B9: 15 | C9: % Enforcing this rule is primarily the CRO's responsibility.
B11: The "disposition effect": a behavioral bias
A13: Exposure Limits:
B14: Any one ETF exposure: | E14: 40 | F14: % of the fund (\10billion)
B15: Any one Country exposure: | E15: 80 | F15: % of the fund (\10billion)
B16: Any Futures Net exposure: | E16: 10 | F16: % of the fund (\10billion) | I16: size(exposure) = underlying asset's price x multiplier x #of contracts (x FX rate)
B17: Any Options Long exposure: | E17: 10 | F17: % of the fund (\10billion)
B18: Any Options Short exposure: | E18: 10 | F18: % of the fund (\10billion)
A20: New Trade | B20: Only on Friday at Friday's closing prices (Order-type: Market-on-Close)
A21: Trade Size | B21: Less than 25% of Daily Trading Volume on previous Thursday
A22: Leverage | B22: up to 30% of the asset at 3.64% p.a.
A23: ETF Borrowing | B23: up to 30% of the asset (at zero cost)
E24: NOTE: Each team should decide on its own limits.
A25: CEO | B25: 김경수
A26: CRO | B26: 박준형 | D26: Check if your orders are in compliance with your team's (self-imposed) risk management rules!
A27: CIO | B27: Jacob
A28: Research | B28: 장단비 | C28: 홍예나
A29: COO | B29: 채영찬
B32: If a loss-cut or profit-taking is triggered by your own conditions, (1) record the day's closing price & the day's FX rate, (2) notify your execution by email to yshin57@skku.edu on the same day, (3) apply the recorded price & FX rate on the valuation report (instead of applying the Friday's closing prices) | K32: 2026
K33: Valuation Report before 3pm on Monday | L33: Order Report before 3pm on Friday
L34: =B4 -> 46304 | M34: 0
J35: 0 | K35: =L34+3 -> 46307 | L35: =L34+7 -> 46311 | M35: 1
J36: 1 | K36: =L35+3 -> 46314 | L36: =L35+7 -> 46318 | M36: 2
J37: 2 | K37: =L36+3 -> 46321 | L37: =L36+7 -> 46325 | M37: 3
J38: 3 | K38: =L37+3 -> 46328 | L38: =L37+7 -> 46332 | M38: 4
J39: 4 | K39: =L38+3 -> 46335 | L39: =L38+7 -> 46339 | M39: 5
J40: 5 | K40: =L39+3 -> 46342 | L40: =L39+7 -> 46346 | M40: 6
J41: 6 | K41: =L40+3 -> 46349

Sheet 09-Oct
A1: ='Risk Mgmt'!A1 -> DBA4014 | C1: Valuation at Inception | J1: as of | K1: =TEXT(B4,"YYYY-MM-DD") -> 2026-10-09
A3: Company | B3: DBA4 | D3: CEO | E3: CRO | F3: CIO | G3: ='Risk Mgmt'!B27 -> Jacob | H3: Research | I3: ='Risk Mgmt'!B28 -> 장단비 | J3: COO | K3: ='Risk Mgmt'!B29 -> 채영찬
A4: Trade Date | B4: ='Risk Mgmt'!B4 -> 46304 | C4: =IF(WEEKDAY(B4)=1,"SUN",IF(WEEKDAY(B4)=2,"MON",IF(WEEKDAY(B4)=3,"TUE",IF(WEEKDAY(B4)=4,"WED",IF(WEEKDAY(B4)=5,"THU",IF(WEEKDAY(B4)=6,"FRI",IF(WEEKDAY(B4)=7,"SAT","-"))))))) -> FRI | D4: ='Risk Mgmt'!B25 -> 김경수 | E4: ='Risk Mgmt'!B26 -> 박준형 | G4: ='Risk Mgmt'!C27 -> 0 | I4: ='Risk Mgmt'!C28 -> 홍예나 | K4: ='Risk Mgmt'!C29 -> 0
A5: Report Date | B5: =B4+3 -> 46307 | C5: =IF(WEEKDAY(B5)=1,"SUN",IF(WEEKDAY(B5)=2,"MON",IF(WEEKDAY(B5)=3,"TUE",IF(WEEKDAY(B5)=4,"WED",IF(WEEKDAY(B5)=5,"THU",IF(WEEKDAY(B5)=6,"FRI",IF(WEEKDAY(B5)=7,"SAT","-"))))))) -> MON
A6: 10000000000 | D6: Risk Mgmt Rules | E6: Loss-cut | F6: Profit-taking | G6: ETF | H6: Country | I6: Futures | J6: Options L | K6: Options S
A7: Cash Balace (KRW, before trades) | E7: ='Risk Mgmt'!B7/100 -> 0.1 | F7: ='Risk Mgmt'!B9/100 -> 0.15 | G7: ='Risk Mgmt'!E14/100 -> 0.4 | H7: ='Risk Mgmt'!E15/100 -> 0.8 | I7: ='Risk Mgmt'!E16/100 -> 0.1 | J7: ='Risk Mgmt'!E17/100 -> 0.1 | K7: ='Risk Mgmt'!E18/100 -> 0.1
A9: New Positions | E9: 1 | F9: 2 | G9: 3 | H9: 4 | I9: 5 | J9: 6 | K9: 7 | L9: 8
A10: Long or Short | E10: Long | F10: Long | G10: Long | H10: Long | I10: Long | J10: Long
A11: Product Name | E11: KODEX 200 | F11: SPDR S&P 500 ETF Trust | G11: VanEck Semiconductor ETF | H11: First Trust Nasdaq Cybersecurity ETF | I11: SPDR Bloomberg 1-3 Month T-Bill ETF | J11: Schwab U.S. Dividend Equity ETF
A12: Product Code | E12: A069500 | F12: SPY | G12: SMH | H12: CIBR | I12: BIL | J12: SCHD
A13: Product Type (ETF/Futures/Options) | E13: ETF | F13: ETF | G13: ETF | H13: ETF | I13: ETF | J13: ETF
A14: Size (shares/contracts) | E14: 23663 | F14: 2400 | G14: 1790 | H14: 7001 | I14: 8159 | J14: 34001
A15: Multiple (Futures&Options) | E15: 1 | F15: 1 | G15: 1 | H15: 1 | I15: 1 | J15: 1
A16: Booking/Opening Price | E16: 105650 | F16: 778.57 | G16: 603.33 | H16: 110 | I16: 91.51 | J16: 33.04
A17: Booking/Opening FX (exchange rate) | E17: 1 | F17: 1342 | G17: 1342 | H17: 1342 | I17: 1342 | J17: 1342
A18: Booking/Opening Price(converted to KRW) | E18: =E16*E17 -> 105650 | F18: =F16*F17 -> 1044840.9 | G18: =G16*G17 -> 809668.86 | H18: =H16*H17 -> 147620 | I18: =I16*I17 -> 122806.42 | J18: =J16*J17 -> 44339.68 | K18: =K17*K16 -> 0 | L18: =L17*L16 -> 0
A20: Booking Price(KRW) x Size | E20: =E14*E15*E18 -> 2499995950 | F20: =F14*F15*F18 -> 2507618256 | G20: =G14*G15*G18 -> 1.4493073e+09 | H20: =H14*H15*H18 -> 1033487620 | I20: =I14*I15*I18 -> 1.0019776e+09 | J20: =J14*J15*J18 -> 1.5075935e+09 | K20: =K14*K15*K18 -> 0 | L20: =L14*L15*L18 -> 0
A21: Cashflow: Buy(-), Sell(+) | D21: =SUM(E21:AP21) -> -9.9999801e+09 | E21: =IF(E10="Long",-E20,IF(E10="Short",E20,0)) -> -2499995950 | F21: =IF(F10="Long",-F20,IF(F10="Short",F20,0)) -> -2507618256 | G21: =IF(G10="Long",-G20,IF(G10="Short",G20,0)) -> -1.4493073e+09 | H21: =IF(H10="Long",-H20,IF(H10="Short",H20,0)) -> -1033487620 | I21: =IF(I10="Long",-I20,IF(I10="Short",I20,0)) -> -1.0019776e+09 | J21: =IF(J10="Long",-J20,IF(J10="Short",J20,0)) -> -1.5075935e+09 | K21: =IF(K10="Long",-K20,IF(K10="Short",K20,"None")) -> None | L21: =IF(L10="Long",-L20,IF(L10="Short",L20,"None")) -> None
D22: Net Cashflow
D24: =A6+D21 -> 19874.14
D25: New Cash Balance
A27: =IF(D24>0,"+"," ") -> + | B27: =IF(D24>0,0.035%,0.07%) -> 0.00035 | D27: =D24*(1+B27) -> 19881.096
D28: Nextweek Cash Balance

Sheet 16-Oct
A1: ='Risk Mgmt'!A1 -> DBA4014 | C1: 1st week Valuation | J1: as of | K1: =TEXT(B4,"YYYY-MM-DD") -> 2026-10-16
A3: Company | B3: ='09-Oct'!B3:B3 -> DBA4 | D3: CEO | E3: CRO | F3: CIO | G3: ='Risk Mgmt'!B27 -> Jacob | H3: Research | I3: ='Risk Mgmt'!B28 -> 장단비 | J3: COO | K3: ='Risk Mgmt'!B29 -> 채영찬
A4: Trade Date | B4: ='09-Oct'!B4+7 -> 46311 | C4: =IF(WEEKDAY(B4)=1,"SUN",IF(WEEKDAY(B4)=2,"MON",IF(WEEKDAY(B4)=3,"TUE",IF(WEEKDAY(B4)=4,"WED",IF(WEEKDAY(B4)=5,"THU",IF(WEEKDAY(B4)=6,"FRI",IF(WEEKDAY(B4)=7,"SAT","-"))))))) -> FRI | D4: ='Risk Mgmt'!B25 -> 김경수 | E4: ='Risk Mgmt'!B26 -> 박준형 | G4: ='Risk Mgmt'!C27 -> 0 | I4: ='Risk Mgmt'!C28 -> 홍예나 | K4: ='Risk Mgmt'!C29 -> 0
A5: Report Date | B5: =B4+3 -> 46314 | C5: =IF(WEEKDAY(B5)=1,"SUN",IF(WEEKDAY(B5)=2,"MON",IF(WEEKDAY(B5)=3,"TUE",IF(WEEKDAY(B5)=4,"WED",IF(WEEKDAY(B5)=5,"THU",IF(WEEKDAY(B5)=6,"FRI",IF(WEEKDAY(B5)=7,"SAT","-"))))))) -> MON
B6: ='09-Oct'!D27 -> 19881.096 | D6: Risk Mgmt Rules | E6: Loss-cut | F6: Profit-taking | G6: ETF | H6: Country | I6: Futures | J6: Options L | K6: Options S
A7: Cash Balace (KRW, before trades) | E7: ='09-Oct'!E7 -> 0.1 | F7: ='09-Oct'!F7 -> 0.15 | G7: ='09-Oct'!G7 -> 0.4 | H7: ='09-Oct'!H7 -> 0.8 | I7: ='09-Oct'!I7 -> 0.1 | J7: ='09-Oct'!J7 -> 0.1 | K7: ='09-Oct'!K7 -> 0.1
A9: Previous Positions | E9: 1 | F9: 2 | G9: 3 | H9: 4 | I9: 5 | J9: 6 | K9: 7 | L9: 8
A10: Long or Short | E10: ='09-Oct'!E10 -> Long | F10: ='09-Oct'!F10 -> Long | G10: ='09-Oct'!G10 -> Long | H10: ='09-Oct'!H10 -> Long | I10: ='09-Oct'!I10 -> Long | J10: ='09-Oct'!J10 -> Long | K10: ='09-Oct'!K10 -> 0 | L10: ='09-Oct'!L10 -> 0
A11: Product Name | E11: ='09-Oct'!E11 -> KODEX 200 | F11: ='09-Oct'!F11 -> SPDR S&P 500 ETF Trust | G11: ='09-Oct'!G11 -> VanEck Semiconductor ETF | H11: ='09-Oct'!H11 -> First Trust Nasdaq Cybersecurity ETF | I11: ='09-Oct'!I11 -> SPDR Bloomberg 1-3 Month T-Bill ETF | J11: ='09-Oct'!J11 -> Schwab U.S. Dividend Equity ETF | K11: ='09-Oct'!K11 -> 0 | L11: ='09-Oct'!L11 -> 0
A12: Product Code | E12: ='09-Oct'!E12 -> A069500 | F12: ='09-Oct'!F12 -> SPY | G12: ='09-Oct'!G12 -> SMH | H12: ='09-Oct'!H12 -> CIBR | I12: ='09-Oct'!I12 -> BIL | J12: ='09-Oct'!J12 -> SCHD | K12: ='09-Oct'!K12 -> 0 | L12: ='09-Oct'!L12 -> 0
A13: Product Type (ETF/Futures/Options) | E13: ='09-Oct'!E13 -> ETF | F13: ='09-Oct'!F13 -> ETF | G13: ='09-Oct'!G13 -> ETF | H13: ='09-Oct'!H13 -> ETF | I13: ='09-Oct'!I13 -> ETF | J13: ='09-Oct'!J13 -> ETF | K13: ='09-Oct'!K13 -> 0 | L13: ='09-Oct'!L13 -> 0
A14: Size (shares/contracts) | E14: ='09-Oct'!E14 -> 23663 | F14: ='09-Oct'!F14 -> 2400 | G14: ='09-Oct'!G14 -> 1790 | H14: ='09-Oct'!H14 -> 7001 | I14: ='09-Oct'!I14 -> 8159 | J14: ='09-Oct'!J14 -> 34001 | K14: ='09-Oct'!K14 -> 0 | L14: ='09-Oct'!L14 -> 0
A15: Multiple (Futures&Options) | E15: ='09-Oct'!E15 -> 1 | F15: ='09-Oct'!F15 -> 1 | G15: ='09-Oct'!G15 -> 1 | H15: ='09-Oct'!H15 -> 1 | I15: ='09-Oct'!I15 -> 1 | J15: ='09-Oct'!J15 -> 1 | K15: ='09-Oct'!K15 -> 0 | L15: ='09-Oct'!L15 -> 0
A18: New Trades | E18: 1 | F18: 2 | G18: 3 | H18: 4 | I18: 5 | J18: 6 | K18: 7 | L18: 8
A19: Buy or Sell | E19: Sell | F19: Sell | G19: Sell | H19: Buy | I19: Buy | J19: Buy | K19: Sell | L19: Sell
A20: Product Name | E20: KODEX 200 | F20: VanEck Semiconductor ETF | G20: First Trust Nasdaq Cybersecurity ETF | H20: State Street Health Care Select Sector SPDR ETF | I20: State Street Consumer Staples Select Sector SPDR ETF | J20: State Street Energy Select Sector SPDR ETF | K20: VanEck Semiconductor ETF | L20: First Trust Nasdaq Cybersecurity ETF
A21: Product Code | E21: A069500 | F21: SMH | G21: CIBR | H21: XLV | I21: XLP | J21: XLE | K21: SMH | L21: CIBR
A22: Product Type (ETF/Futures/Options) | E22: ETF | F22: ETF | G22: ETF | H22: ETF | I22: ETF | J22: ETF | K22: ETF | L22: ETF
A23: Size (shares/contracts) | E23: 23663 | F23: 1151 | G23: 3549 | H23: 2420 | I23: 3298 | J23: 3221 | K23: 639 | L23: 3452
A24: Multiple (Futures&Options) | E24: 1 | F24: 1 | G24: 1 | H24: 1 | I24: 1 | J24: 1 | K24: 1 | L24: 1
A25: ="New Price ("&TEXT($B$4,"yyyy-mm-dd")&")" -> New Price (2026-10-16) | E25: 94805 | F25: 539.79 | G25: 98.82 | H25: 176.71 | I25: 87.62 | J25: 68.24 | K25: 539.79 | L25: 98.82
A26: ="New FX (exchange rate) ("&TEXT($B$4,"yyyy-mm-dd")&")" -> New FX (exchange rate) (2026-10-16) | E26: 1 | F26: 1336.8 | G26: 1336.8 | H26: 1336.8 | I26: 1336.8 | J26: 1336.8 | K26: 1336.8 | L26: 1336.8
A27: ="New Converted Price ("&TEXT($B$4,"yyyy-mm-dd")&")" -> New Converted Price (2026-10-16) | E27: =E26*E25 -> 94805 | F27: =F26*F25 -> 721591.27 | G27: =G26*G25 -> 132102.58 | H27: =H26*H25 -> 236225.93 | I27: =I26*I25 -> 117130.42 | J27: =J26*J25 -> 91223.232 | K27: =K26*K25 -> 721591.27 | L27: =L26*L25 -> 132102.58
A28: Cashflow: Buy(-), Sell(+) | D28: =SUM(E28:AP28) -> 3.2080763e+09 | E28: =IF(E19="Buy",-E23*E24*E27,IF(E19="Sell",+E23*E24*E27,"None")) -> 2243370715 | F28: =IF(F19="Buy",-F23*F24*F27,IF(F19="Sell",+F23*F24*F27,"None")) -> 8.3055155e+08 | G28: =IF(G19="Buy",-G23*G24*G27,IF(G19="Sell",+G23*G24*G27,"None")) -> 4.6883204e+08 | H28: =IF(H19="Buy",-H23*H24*H27,IF(H19="Sell",+H23*H24*H27,"None")) -> -5.7166675e+08 | I28: =IF(I19="Buy",-I23*I24*I27,IF(I19="Sell",+I23*I24*I27,"None")) -> -3.8629611e+08 | J28: =IF(J19="Buy",-J23*J24*J27,IF(J19="Sell",+J23*J24*J27,"None")) -> -2.9383003e+08 | K28: =IF(K19="Buy",-K23*K24*K27,IF(K19="Sell",+K23*K24*K27,"None")) -> 4.6109682e+08 | L28: =IF(L19="Buy",-L23*L27,IF(L19="Sell",+L23*L27,"None")) -> 4.5601809e+08
D29: Net Cashflow
D31: =B6+D28 -> 3.2080962e+09
D32: New Cash Balance
A34: =IF(D31>0,"+"," ") -> + | B34: =IF(D31>0,0.035%,0.07%) -> 0.00035 | D34: =D31*(1+B34) -> 3.2092191e+09
D35: Nextweek Cash Balance
A37: Outstanding (New) Positions | E37: 1 | G37: 3 | H37: 4 | I37: 5 | J37: 6 | K37: 7 | L37: 8
A38: Long or Short | E38: Long | F38: Long | G38: Long | H38: Long | I38: Long | J38: Long
A39: Product Name | E39: SPDR S&P 500 ETF Trust | F39: SPDR Bloomberg 1-3 Month T-Bill ETF | G39: Schwab U.S. Dividend Equity ETF | H39: State Street Health Care Select Sector SPDR ETF | I39: State Street Consumer Staples Select Sector SPDR ETF | J39: State Street Energy Select Sector SPDR ETF
A40: Product Code | E40: SPY | F40: BIL | G40: SCHD | H40: XLV | I40: XLP | J40: XLE
A41: Product Type (ETF/Futures/Options) | E41: ETF | F41: ETF | G41: ETF | H41: ETF | I41: ETF | J41: ETF
A42: Size (shares/contracts) | E42: 2400 | F42: 8159 | G42: 34001 | H42: 2420 | I42: 3298 | J42: 3221
A43: Multiple (Futures&Options) | E43: 1 | F43: 1 | G43: 1 | H43: 1 | I43: 1 | J43: 1
A44: ="New Price ("&TEXT($B$4,"yyyy-mm-dd")&")" -> New Price (2026-10-16) | E44: 763.25 | F44: 91.57 | G44: 34.35 | H44: 176.71 | I44: 87.62 | J44: 68.24
A45: ="New FX (exchange rate) ("&TEXT($B$4,"yyyy-mm-dd")&")" -> New FX (exchange rate) (2026-10-16) | E45: 1336.8 | F45: 1336.8 | G45: 1336.8 | H45: 1336.8 | I45: 1336.8 | J45: 1336.8
A46: ="New Converted Price ("&TEXT($B$4,"yyyy-mm-dd")&")" -> New Converted Price (2026-10-16) | E46: =E45*E44 -> 1020312.6 | F46: =F45*F44 -> 122410.78 | G46: =G45*G44 -> 45919.08 | H46: =H45*H44 -> 236225.93 | I46: =I45*I44 -> 117130.42 | J46: =J45*J44 -> 91223.232 | K46: =K45*K44 -> 0 | L46: =L45*L44 -> 0
A47: Market Values of ETFs | D47: =SUM(E47:AP47) -> 6.2605873e+09 | E47: =IF(E38="Long",E42*E43*E46,IF(E38="Short",-E42*E43*E46,"None")) -> 2448750240 | F47: =IF(F38="Long",F42*F43*F46,IF(F38="Short",-F42*F43*F46,"None")) -> 9.9874952e+08 | G47: =IF(G38="Long",G42*G43*G46,IF(G38="Short",-G42*G43*G46,"None")) -> 1.5612946e+09 | H47: =IF(H38="Long",H42*H43*H46,IF(H38="Short",-H42*H43*H46,"None")) -> 5.7166675e+08 | I47: =IF(I38="Long",I42*I43*I46,IF(I38="Short",-I42*I43*I46,"None")) -> 3.8629611e+08 | J47: =IF(J38="Long",J42*J43*J46,IF(J38="Short",-J42*J43*J46,"None")) -> 2.9383003e+08 | K47: =IF(K38="Long",K42*K43*K46,IF(K38="Short",-K42*K43*K46,"None")) -> None | L47: =IF(L38="Long",L42*L43*L46,IF(L38="Short",-L42*L43*L46,"None")) -> None
...

Sheet 23-Oct
A1: ='Risk Mgmt'!A1 -> DBA4014 | C1: 2nd week Valuation | J1: as of | K1: =TEXT(B4,"YYYY-MM-DD") -> 2026-10-23
A3: Company | B3: ='16-Oct'!B3:B3 -> DBA4 | D3: CEO | E3: CRO | F3: CIO | G3: ='Risk Mgmt'!B27 -> Jacob | H3: Research | I3: ='Risk Mgmt'!B28 -> 장단비 | J3: COO | K3: ='Risk Mgmt'!B29 -> 채영찬
A4: Trade Date | B4: ='16-Oct'!B4+7 -> 46318 | C4: =IF(WEEKDAY(B4)=1,"SUN",IF(WEEKDAY(B4)=2,"MON",IF(WEEKDAY(B4)=3,"TUE",IF(WEEKDAY(B4)=4,"WED",IF(WEEKDAY(B4)=5,"THU",IF(WEEKDAY(B4)=6,"FRI",IF(WEEKDAY(B4)=7,"SAT","-"))))))) -> FRI | D4: ='Risk Mgmt'!B25 -> 김경수 | E4: ='Risk Mgmt'!B26 -> 박준형 | G4: ='Risk Mgmt'!C27 -> 0 | I4: ='Risk Mgmt'!C28 -> 홍예나 | K4: ='Risk Mgmt'!C29 -> 0
A5: Report Date | B5: =B4+3 -> 46321 | C5: =IF(WEEKDAY(B5)=1,"SUN",IF(WEEKDAY(B5)=2,"MON",IF(WEEKDAY(B5)=3,"TUE",IF(WEEKDAY(B5)=4,"WED",IF(WEEKDAY(B5)=5,"THU",IF(WEEKDAY(B5)=6,"FRI",IF(WEEKDAY(B5)=7,"SAT","-"))))))) -> MON
B6: ='16-Oct'!D34 -> 19888.054 | D6: Risk Mgmt Rules | E6: Loss-cut | F6: Profit-taking | G6: ETF | H6: Country | I6: Futures | J6: Options L | K6: Options S
A7: Cash Balace (KRW, before trades) | E7: ='16-Oct'!E7 -> 0.1 | F7: ='16-Oct'!F7 -> 0.15 | G7: ='16-Oct'!G7 -> 0.4 | H7: ='16-Oct'!H7 -> 0.8 | I7: ='16-Oct'!I7 -> 0.1 | J7: ='16-Oct'!J7 -> 0.1 | K7: ='16-Oct'!K7 -> 0.1
A9: Previous Positions | E9: 1 | F9: 2 | G9: 3 | H9: 4 | I9: 5 | J9: 6 | K9: 7 | L9: 8
A10: Long or Short | E10: ='16-Oct'!E38 -> 0 | F10: ='16-Oct'!F38 -> 0 | G10: ='16-Oct'!G38 -> 0 | H10: ='16-Oct'!H38 -> 0 | I10: ='16-Oct'!I38 -> 0 | J10: ='16-Oct'!J38 -> 0 | K10: ='16-Oct'!K38 -> 0 | L10: ='16-Oct'!L38 -> 0
A11: Product Name | E11: ='16-Oct'!E39 -> 0 | F11: ='16-Oct'!F39 -> 0 | G11: ='16-Oct'!G39 -> 0 | H11: ='16-Oct'!H39 -> 0 | I11: ='16-Oct'!I39 -> 0 | J11: ='16-Oct'!J39 -> 0 | K11: ='16-Oct'!K39 -> 0 | L11: ='16-Oct'!L39 -> 0
A12: Product Code | E12: ='16-Oct'!E40 -> 0 | F12: ='16-Oct'!F40 -> 0 | G12: ='16-Oct'!G40 -> 0 | H12: ='16-Oct'!H40 -> 0 | I12: ='16-Oct'!I40 -> 0 | J12: ='16-Oct'!J40 -> 0 | K12: ='16-Oct'!K40 -> 0 | L12: ='16-Oct'!L40 -> 0
A13: Product Type (ETF/Futures/Options) | E13: ='16-Oct'!E41 -> 0 | F13: ='16-Oct'!F41 -> 0 | G13: ='16-Oct'!G41 -> 0 | H13: ='16-Oct'!H41 -> 0 | I13: ='16-Oct'!I41 -> 0 | J13: ='16-Oct'!J41 -> 0 | K13: ='16-Oct'!K41 -> 0 | L13: ='16-Oct'!L41 -> 0
A14: Size (shares/contracts) | E14: ='16-Oct'!E42 -> 0 | F14: ='16-Oct'!F42 -> 0 | G14: ='16-Oct'!G42 -> 0 | H14: ='16-Oct'!H42 -> 0 | I14: ='16-Oct'!I42 -> 0 | J14: ='16-Oct'!J42 -> 0 | K14: ='16-Oct'!K42 -> 0 | L14: ='16-Oct'!L42 -> 0
A15: Multiple (Futures&Options) | E15: ='16-Oct'!E43 -> 0 | F15: ='16-Oct'!F43 -> 0 | G15: ='16-Oct'!G43 -> 0 | H15: ='16-Oct'!H43 -> 0 | I15: ='16-Oct'!I43 -> 0 | J15: ='16-Oct'!J43 -> 0 | K15: ='16-Oct'!K43 -> 0 | L15: ='16-Oct'!L43 -> 0
A18: New Trades | E18: 1 | F18: 2 | G18: 3 | H18: 4 | I18: 5 | J18: 6 | K18: 7 | L18: 8
A19: Buy or Sell
A20: Product Name
A21: Product Code
A22: Product Type (ETF/Futures/Options)
A23: Size (shares/contracts)
A24: Multiple (Futures&Options)
A25: ="New Price ("&TEXT($B$4,"yyyy-mm-dd")&")" -> New Price (2026-10-23)
A26: ="New FX (exchange rate) ("&TEXT($B$4,"yyyy-mm-dd")&")" -> New FX (exchange rate) (2026-10-23)
A27: ="New Converted Price ("&TEXT($B$4,"yyyy-mm-dd")&")" -> New Converted Price (2026-10-23) | E27: =E26*E25 -> 0 | F27: =F26*F25 -> 0 | G27: =G26*G25 -> 0 | H27: =H26*H25 -> 0 | I27: =I26*I25 -> 0 | J27: =J26*J25 -> 0 | K27: =K26*K25 -> 0 | L27: =L26*L25 -> 0
A28: Cashflow: Buy(-), Sell(+) | D28: =SUM(E28:AF28) -> 0 | E28: =IF(E19="Buy",-E23*E24*E27,IF(E19="Sell",+E23*E24*E27,"None")) -> None | F28: =IF(F19="Buy",-F23*F24*F27,IF(F19="Sell",+F23*F24*F27,"None")) -> None | G28: =IF(G19="Buy",-G23*G24*G27,IF(G19="Sell",+G23*G24*G27,"None")) -> None | H28: =IF(H19="Buy",-H23*H24*H27,IF(H19="Sell",+H23*H24*H27,"None")) -> None | I28: =IF(I19="Buy",-I23*I24*I27,IF(I19="Sell",+I23*I24*I27,"None")) -> None | J28: =IF(J19="Buy",-J23*J24*J27,IF(J19="Sell",+J23*J24*J27,"None")) -> None | K28: =IF(K19="Buy",-K23*K24*K27,IF(K19="Sell",+K23*K24*K27,"None")) -> None | L28: =IF(L19="Buy",-L23*L24*L27,IF(L19="Sell",+L23*L24*L27,"None")) -> None
D29: Net Cashflow
D31: =B6+D28 -> 19888.054
D32: New Cash Balance
A34: =IF(D31>0,"+"," ") -> + | B34: =IF(D31>0,0.035%,0.07%) -> 0.00035 | D34: =D31*(1+B34) -> 19895.015
D35: Nextweek Cash Balance
A37: Outstanding (New) Positions | E37: 1 | F37: 2 | G37: 3 | H37: 4 | I37: 5 | J37: 6 | K37: 7 | L37: 8
A38: Long or Short
A39: Product Name
A40: Product Code
A41: Product Type (ETF/Futures/Options)
A42: Size (shares/contracts)
A43: Multiple (Futures&Options)
A44: ="New Price ("&TEXT($B$4,"yyyy-mm-dd")&")" -> New Price (2026-10-23)
A45: ="New FX (exchange rate) ("&TEXT($B$4,"yyyy-mm-dd")&")" -> New FX (exchange rate) (2026-10-23)
A46: ="New Converted Price ("&TEXT($B$4,"yyyy-mm-dd")&")" -> New Converted Price (2026-10-23) | E46: =E45*E44 -> 0 | F46: =F45*F44 -> 0 | G46: =G45*G44 -> 0 | H46: =H45*H44 -> 0 | I46: =I45*I44 -> 0 | J46: =J45*J44 -> 0 | K46: =K45*K44 -> 0 | L46: =L45*L44 -> 0
A47: Market Values of ETFs | D47: =SUM(E47:AF47) -> 0 | E47: =IF(E38="Long",E42*E43*E46,IF(E38="Short",-E42*E43*E46,"None")) -> None | F47: =IF(F38="Long",F42*F43*F46,IF(F38="Short",-F42*F43*F46,"None")) -> None | G47: =IF(G38="Long",G42*G43*G46,IF(G38="Short",-G42*G43*G46,"None")) -> None | H47: =IF(H38="Long",H42*H43*H46,IF(H38="Short",-H42*H43*H46,"None")) -> None | I47: =IF(I38="Long",I42*I43*I46,IF(I38="Short",-I42*I43*I46,"None")) -> None | J47: =IF(J38="Long",J42*J43*J46,IF(J38="Short",-J42*J43*J46,"None")) -> None | K47: =IF(K38="Long",K42*K43*K46,IF(K38="Short",-K42*K43*K46,"None")) -> None | L47: =IF(L38="Long",L42*L43*L46,IF(L38="Short",-L42*L43*L46,"None")) -> None
...

Sheet 30-Oct
A1: ='Risk Mgmt'!A1 -> DBA4014 | C1: 3rd week Valuation | J1: as of | K1: =TEXT(B4,"YYYY-MM-DD") -> 2026-10-30
A3: Company | B3: ='23-Oct'!B3:B3 -> DBA4 | D3: CEO | E3: CRO | F3: CIO | G3: ='Risk Mgmt'!B27 -> Jacob | H3: Research | I3: ='Risk Mgmt'!B28 -> 장단비 | J3: COO | K3: ='Risk Mgmt'!B29 -> 채영찬
A4: Trade Date | B4: ='23-Oct'!B4+7 -> 46325 | C4: =IF(WEEKDAY(B4)=1,"SUN",IF(WEEKDAY(B4)=2,"MON",IF(WEEKDAY(B4)=3,"TUE",IF(WEEKDAY(B4)=4,"WED",IF(WEEKDAY(B4)=5,"THU",IF(WEEKDAY(B4)=6,"FRI",IF(WEEKDAY(B4)=7,"SAT","-"))))))) -> FRI | D4: ='Risk Mgmt'!B25 -> 김경수 | E4: ='Risk Mgmt'!B26 -> 박준형 | G4: ='Risk Mgmt'!C27 -> 0 | I4: ='Risk Mgmt'!C28 -> 홍예나 | K4: ='Risk Mgmt'!C29 -> 0
A5: Report Date | B5: =B4+3 -> 46328 | C5: =IF(WEEKDAY(B5)=1,"SUN",IF(WEEKDAY(B5)=2,"MON",IF(WEEKDAY(B5)=3,"TUE",IF(WEEKDAY(B5)=4,"WED",IF(WEEKDAY(B5)=5,"THU",IF(WEEKDAY(B5)=6,"FRI",IF(WEEKDAY(B5)=7,"SAT","-"))))))) -> MON
B6: ='23-Oct'!D34 -> 19895.015 | D6: Risk Mgmt Rules | E6: Loss-cut | F6: Profit-taking | G6: ETF | H6: Country | I6: Futures | J6: Options L | K6: Options S
A7: Cash Balace (KRW, before trades) | E7: ='23-Oct'!E7 -> 0.1 | F7: ='23-Oct'!F7 -> 0.15 | G7: ='23-Oct'!G7 -> 0.4 | H7: ='23-Oct'!H7 -> 0.8 | I7: ='23-Oct'!I7 -> 0.1 | J7: ='23-Oct'!J7 -> 0.1 | K7: ='23-Oct'!K7 -> 0.1
A9: Previous Positions | E9: 1 | F9: 2 | G9: 3 | H9: 4 | I9: 5 | J9: 6 | K9: 7 | L9: 8
A10: Long or Short | E10: ='23-Oct'!E38 -> 0 | F10: ='23-Oct'!F38 -> 0 | G10: ='23-Oct'!G38 -> 0 | H10: ='23-Oct'!H38 -> 0 | I10: ='23-Oct'!I38 -> 0 | J10: ='23-Oct'!J38 -> 0 | K10: ='23-Oct'!K38 -> 0 | L10: ='23-Oct'!L38 -> 0
A11: Product Name | E11: ='23-Oct'!E39 -> 0 | F11: ='23-Oct'!F39 -> 0 | G11: ='23-Oct'!G39 -> 0 | H11: ='23-Oct'!H39 -> 0 | I11: ='23-Oct'!I39 -> 0 | J11: ='23-Oct'!J39 -> 0 | K11: ='23-Oct'!K39 -> 0 | L11: ='23-Oct'!L39 -> 0
A12: Product Code | E12: ='23-Oct'!E40 -> 0 | F12: ='23-Oct'!F40 -> 0 | G12: ='23-Oct'!G40 -> 0 | H12: ='23-Oct'!H40 -> 0 | I12: ='23-Oct'!I40 -> 0 | J12: ='23-Oct'!J40 -> 0 | K12: ='23-Oct'!K40 -> 0 | L12: ='23-Oct'!L40 -> 0
A13: Product Type (ETF/Futures/Options) | E13: ='23-Oct'!E41 -> 0 | F13: ='23-Oct'!F41 -> 0 | G13: ='23-Oct'!G41 -> 0 | H13: ='23-Oct'!H41 -> 0 | I13: ='23-Oct'!I41 -> 0 | J13: ='23-Oct'!J41 -> 0 | K13: ='23-Oct'!K41 -> 0 | L13: ='23-Oct'!L41 -> 0
A14: Size (shares/contracts) | E14: ='23-Oct'!E42 -> 0 | F14: ='23-Oct'!F42 -> 0 | G14: ='23-Oct'!G42 -> 0 | H14: ='23-Oct'!H42 -> 0 | I14: ='23-Oct'!I42 -> 0 | J14: ='23-Oct'!J42 -> 0 | K14: ='23-Oct'!K42 -> 0 | L14: ='23-Oct'!L42 -> 0
A15: Multiple (Futures&Options) | E15: ='23-Oct'!E43 -> 0 | F15: ='23-Oct'!F43 -> 0 | G15: ='23-Oct'!G43 -> 0 | H15: ='23-Oct'!H43 -> 0 | I15: ='23-Oct'!I43 -> 0 | J15: ='23-Oct'!J43 -> 0 | K15: ='23-Oct'!K43 -> 0 | L15: ='23-Oct'!L43 -> 0
A18: New Trades | E18: 1 | F18: 2 | G18: 3 | H18: 4 | I18: 5 | J18: 6 | K18: 7 | L18: 8
A19: Buy or Sell
A20: Product Name
A21: Product Code
A22: Product Type (ETF/Futures/Options)
A23: Size (shares/contracts)
A24: Multiple (Futures&Options)
A25: ="New Price ("&TEXT($B$4,"yyyy-mm-dd")&")" -> New Price (2026-10-30)
A26: ="New FX (exchange rate) ("&TEXT($B$4,"yyyy-mm-dd")&")" -> New FX (exchange rate) (2026-10-30)
A27: ="New Converted Price ("&TEXT($B$4,"yyyy-mm-dd")&")" -> New Converted Price (2026-10-30) | E27: =E26*E25 -> 0 | F27: =F26*F25 -> 0 | G27: =G26*G25 -> 0 | H27: =H26*H25 -> 0 | I27: =I26*I25 -> 0 | J27: =J26*J25 -> 0 | K27: =K26*K25 -> 0 | L27: =L26*L25 -> 0
A28: Cashflow: Buy(-), Sell(+) | D28: =SUM(E28:AF28) -> 0 | E28: =IF(E19="Buy",-E23*E24*E27,IF(E19="Sell",+E23*E24*E27,"None")) -> None | F28: =IF(F19="Buy",-F23*F24*F27,IF(F19="Sell",+F23*F24*F27,"None")) -> None | G28: =IF(G19="Buy",-G23*G24*G27,IF(G19="Sell",+G23*G24*G27,"None")) -> None | H28: =IF(H19="Buy",-H23*H24*H27,IF(H19="Sell",+H23*H24*H27,"None")) -> None | I28: =IF(I19="Buy",-I23*I24*I27,IF(I19="Sell",+I23*I24*I27,"None")) -> None | J28: =IF(J19="Buy",-J23*J24*J27,IF(J19="Sell",+J23*J24*J27,"None")) -> None | K28: =IF(K19="Buy",-K23*K24*K27,IF(K19="Sell",+K23*K24*K27,"None")) -> None | L28: =IF(L19="Buy",-L23*L24*L27,IF(L19="Sell",+L23*L24*L27,"None")) -> None
D29: Net Cashflow
D31: =B6+D28 -> 19895.015
D32: New Cash Balance
A34: =IF(D31>0,"+"," ") -> + | B34: =IF(D31>0,0.035%,0.07%) -> 0.00035 | D34: =D31*(1+B34) -> 19901.978
D35: Nextweek Cash Balance
A37: Outstanding (New) Positions | E37: 1 | F37: 2 | G37: 3 | H37: 4 | I37: 5 | J37: 6 | K37: 7 | L37: 8
A38: Long or Short
A39: Product Name
A40: Product Code
A41: Product Type (ETF/Futures/Options)
A42: Size (shares/contracts)
A43: Multiple (Futures&Options)
A44: ="New Price ("&TEXT($B$4,"yyyy-mm-dd")&")" -> New Price (2026-10-30)
A45: ="New FX (exchange rate) ("&TEXT($B$4,"yyyy-mm-dd")&")" -> New FX (exchange rate) (2026-10-30)
A46: ="New Converted Price ("&TEXT($B$4,"yyyy-mm-dd")&")" -> New Converted Price (2026-10-30) | E46: =E45*E44 -> 0 | F46: =F45*F44 -> 0 | G46: =G45*G44 -> 0 | H46: =H45*H44 -> 0 | I46: =I45*I44 -> 0 | J46: =J45*J44 -> 0 | K46: =K45*K44 -> 0 | L46: =L45*L44 -> 0
A47: Market Values of ETFs | D47: =SUM(E47:AF47) -> 0 | E47: =IF(E38="Long",E42*E43*E46,IF(E38="Short",-E42*E43*E46,"None")) -> None | F47: =IF(F38="Long",F42*F43*F46,IF(F38="Short",-F42*F43*F46,"None")) -> None | G47: =IF(G38="Long",G42*G43*G46,IF(G38="Short",-G42*G43*G46,"None")) -> None | H47: =IF(H38="Long",H42*H43*H46,IF(H38="Short",-H42*H43*H46,"None")) -> None | I47: =IF(I38="Long",I42*I43*I46,IF(I38="Short",-I42*I43*I46,"None")) -> None | J47: =IF(J38="Long",J42*J43*J46,IF(J38="Short",-J42*J43*J46,"None")) -> None | K47: =IF(K38="Long",K42*K43*K46,IF(K38="Short",-K42*K43*K46,"None")) -> None | L47: =IF(L38="Long",L42*L43*L46,IF(L38="Short",-L42*L43*L46,"None")) -> None
...

Sheet 06-Nov
A1: ='Risk Mgmt'!A1 -> DBA4014 | C1: 4th week Valuation | J1: as of | K1: =TEXT(B4,"YYYY-MM-DD") -> 2026-11-06
A3: Company | B3: ='30-Oct'!B3:B3 -> DBA4 | D3: CEO | E3: CRO | F3: CIO | G3: ='Risk Mgmt'!B27 -> Jacob | H3: Research | I3: ='Risk Mgmt'!B28 -> 장단비 | J3: COO | K3: ='Risk Mgmt'!B29 -> 채영찬
A4: Trade Date | B4: ='30-Oct'!B4+7 -> 46332 | C4: =IF(WEEKDAY(B4)=1,"SUN",IF(WEEKDAY(B4)=2,"MON",IF(WEEKDAY(B4)=3,"TUE",IF(WEEKDAY(B4)=4,"WED",IF(WEEKDAY(B4)=5,"THU",IF(WEEKDAY(B4)=6,"FRI",IF(WEEKDAY(B4)=7,"SAT","-"))))))) -> FRI | D4: ='Risk Mgmt'!B25 -> 김경수 | E4: ='Risk Mgmt'!B26 -> 박준형 | G4: ='Risk Mgmt'!C27 -> 0 | I4: ='Risk Mgmt'!C28 -> 홍예나 | K4: ='Risk Mgmt'!C29 -> 0
A5: Report Date | B5: =B4+3 -> 46335 | C5: =IF(WEEKDAY(B5)=1,"SUN",IF(WEEKDAY(B5)=2,"MON",IF(WEEKDAY(B5)=3,"TUE",IF(WEEKDAY(B5)=4,"WED",IF(WEEKDAY(B5)=5,"THU",IF(WEEKDAY(B5)=6,"FRI",IF(WEEKDAY(B5)=7,"SAT","-"))))))) -> MON
B6: ='30-Oct'!D34 -> 19901.978 | D6: Risk Mgmt Rules | E6: Loss-cut | F6: Profit-taking | G6: ETF | H6: Country | I6: Futures | J6: Options L | K6: Options S
A7: Cash Balace (KRW, before trades) | E7: ='30-Oct'!E7 -> 0.1 | F7: ='30-Oct'!F7 -> 0.15 | G7: ='30-Oct'!G7 -> 0.4 | H7: ='30-Oct'!H7 -> 0.8 | I7: ='30-Oct'!I7 -> 0.1 | J7: ='30-Oct'!J7 -> 0.1 | K7: ='30-Oct'!K7 -> 0.1
A9: Previous Positions | E9: 1 | F9: 2 | G9: 3 | H9: 4 | I9: 5 | J9: 6 | K9: 7 | L9: 8
A10: Long or Short | E10: ='30-Oct'!E38 -> 0 | F10: ='30-Oct'!F38 -> 0 | G10: ='30-Oct'!G38 -> 0 | H10: ='30-Oct'!H38 -> 0 | I10: ='30-Oct'!I38 -> 0 | J10: ='30-Oct'!J38 -> 0 | K10: ='30-Oct'!K38 -> 0 | L10: ='30-Oct'!L38 -> 0
A11: Product Name | E11: ='30-Oct'!E39 -> 0 | F11: ='30-Oct'!F39 -> 0 | G11: ='30-Oct'!G39 -> 0 | H11: ='30-Oct'!H39 -> 0 | I11: ='30-Oct'!I39 -> 0 | J11: ='30-Oct'!J39 -> 0 | K11: ='30-Oct'!K39 -> 0 | L11: ='30-Oct'!L39 -> 0
A12: Product Code | E12: ='30-Oct'!E40 -> 0 | F12: ='30-Oct'!F40 -> 0 | G12: ='30-Oct'!G40 -> 0 | H12: ='30-Oct'!H40 -> 0 | I12: ='30-Oct'!I40 -> 0 | J12: ='30-Oct'!J40 -> 0 | K12: ='30-Oct'!K40 -> 0 | L12: ='30-Oct'!L40 -> 0
A13: Product Type (ETF/Futures/Options) | E13: ='30-Oct'!E41 -> 0 | F13: ='30-Oct'!F41 -> 0 | G13: ='30-Oct'!G41 -> 0 | H13: ='30-Oct'!H41 -> 0 | I13: ='30-Oct'!I41 -> 0 | J13: ='30-Oct'!J41 -> 0 | K13: ='30-Oct'!K41 -> 0 | L13: ='30-Oct'!L41 -> 0
A14: Size (shares/contracts) | E14: ='30-Oct'!E42 -> 0 | F14: ='30-Oct'!F42 -> 0 | G14: ='30-Oct'!G42 -> 0 | H14: ='30-Oct'!H42 -> 0 | I14: ='30-Oct'!I42 -> 0 | J14: ='30-Oct'!J42 -> 0 | K14: ='30-Oct'!K42 -> 0 | L14: ='30-Oct'!L42 -> 0
A15: Multiple (Futures&Options) | E15: ='30-Oct'!E43 -> 0 | F15: ='30-Oct'!F43 -> 0 | G15: ='30-Oct'!G43 -> 0 | H15: ='30-Oct'!H43 -> 0 | I15: ='30-Oct'!I43 -> 0 | J15: ='30-Oct'!J43 -> 0 | K15: ='30-Oct'!K43 -> 0 | L15: ='30-Oct'!L43 -> 0
A18: New Trades | E18: 1 | F18: 2 | G18: 3 | H18: 4 | I18: 5 | J18: 6 | K18: 7 | L18: 8
A19: Buy or Sell
A20: Product Name
A21: Product Code
A22: Product Type (ETF/Futures/Options)
A23: Size (shares/contracts)
A24: Multiple (Futures&Options)
A25: ="New Price ("&TEXT($B$4,"yyyy-mm-dd")&")" -> New Price (2026-11-06)
A26: ="New FX (exchange rate) ("&TEXT($B$4,"yyyy-mm-dd")&")" -> New FX (exchange rate) (2026-11-06)
A27: ="New Converted Price ("&TEXT($B$4,"yyyy-mm-dd")&")" -> New Converted Price (2026-11-06) | E27: =E26*E25 -> 0 | F27: =F26*F25 -> 0 | G27: =G26*G25 -> 0 | H27: =H26*H25 -> 0 | I27: =I26*I25 -> 0 | J27: =J26*J25 -> 0 | K27: =K26*K25 -> 0 | L27: =L26*L25 -> 0
A28: Cashflow: Buy(-), Sell(+) | D28: =SUM(E28:AF28) -> 0 | E28: =IF(E19="Buy",-E23*E24*E27,IF(E19="Sell",+E23*E24*E27,"None")) -> None | F28: =IF(F19="Buy",-F23*F24*F27,IF(F19="Sell",+F23*F24*F27,"None")) -> None | G28: =IF(G19="Buy",-G23*G24*G27,IF(G19="Sell",+G23*G24*G27,"None")) -> None | H28: =IF(H19="Buy",-H23*H24*H27,IF(H19="Sell",+H23*H24*H27,"None")) -> None | I28: =IF(I19="Buy",-I23*I24*I27,IF(I19="Sell",+I23*I24*I27,"None")) -> None | J28: =IF(J19="Buy",-J23*J24*J27,IF(J19="Sell",+J23*J24*J27,"None")) -> None | K28: =IF(K19="Buy",-K23*K24*K27,IF(K19="Sell",+K23*K24*K27,"None")) -> None | L28: =IF(L19="Buy",-L23*L24*L27,IF(L19="Sell",+L23*L24*L27,"None")) -> None
D29: Net Cashflow
D31: =B6+D28 -> 19901.978
D32: New Cash Balance
A34: =IF(D31>0,"+"," ") -> + | B34: =IF(D31>0,0.035%,0.07%) -> 0.00035 | D34: =D31*(1+B34) -> 19908.944
D35: Nextweek Cash Balance
A37: Outstanding (New) Positions | E37: 1 | F37: 2 | G37: 3 | H37: 4 | I37: 5 | J37: 6 | K37: 7 | L37: 8
A38: Long or Short
A39: Product Name
A40: Product Code
A41: Product Type (ETF/Futures/Options)
A42: Size (shares/contracts)
A43: Multiple (Futures&Options)
A44: ="New Price ("&TEXT($B$4,"yyyy-mm-dd")&")" -> New Price (2026-11-06)
A45: ="New FX (exchange rate) ("&TEXT($B$4,"yyyy-mm-dd")&")" -> New FX (exchange rate) (2026-11-06)
A46: ="New Converted Price ("&TEXT($B$4,"yyyy-mm-dd")&")" -> New Converted Price (2026-11-06) | E46: =E45*E44 -> 0 | F46: =F45*F44 -> 0 | G46: =G45*G44 -> 0 | H46: =H45*H44 -> 0 | I46: =I45*I44 -> 0 | J46: =J45*J44 -> 0 | K46: =K45*K44 -> 0 | L46: =L45*L44 -> 0
A47: Market Values of ETFs | D47: =SUM(E47:AF47) -> 0 | E47: =IF(E38="Long",E42*E43*E46,IF(E38="Short",-E42*E43*E46,"None")) -> None | F47: =IF(F38="Long",F42*F43*F46,IF(F38="Short",-F42*F43*F46,"None")) -> None | G47: =IF(G38="Long",G42*G43*G46,IF(G38="Short",-G42*G43*G46,"None")) -> None | H47: =IF(H38="Long",H42*H43*H46,IF(H38="Short",-H42*H43*H46,"None")) -> None | I47: =IF(I38="Long",I42*I43*I46,IF(I38="Short",-I42*I43*I46,"None")) -> None | J47: =IF(J38="Long",J42*J43*J46,IF(J38="Short",-J42*J43*J46,"None")) -> None | K47: =IF(K38="Long",K42*K43*K46,IF(K38="Short",-K42*K43*K46,"None")) -> None | L47: =IF(L38="Long",L42*L43*L46,IF(L38="Short",-L42*L43*L46,"None")) -> None
...

Sheet 13-Nov
A1: ='Risk Mgmt'!A1 -> DBA4014 | C1: 5th week Valuation | J1: as of | K1: =TEXT(B4,"YYYY-MM-DD") -> 2026-11-13
A3: Company | B3: ='30-Oct'!B3:B3 -> DBA4 | D3: CEO | E3: CRO | F3: CIO | G3: ='Risk Mgmt'!B27 -> Jacob | H3: Research | I3: ='Risk Mgmt'!B28 -> 장단비 | J3: COO | K3: ='Risk Mgmt'!B29 -> 채영찬
A4: Trade Date | B4: ='06-Nov'!B4+7 -> 46339 | C4: =IF(WEEKDAY(B4)=1,"SUN",IF(WEEKDAY(B4)=2,"MON",IF(WEEKDAY(B4)=3,"TUE",IF(WEEKDAY(B4)=4,"WED",IF(WEEKDAY(B4)=5,"THU",IF(WEEKDAY(B4)=6,"FRI",IF(WEEKDAY(B4)=7,"SAT","-"))))))) -> FRI | D4: ='Risk Mgmt'!B25 -> 김경수 | E4: ='Risk Mgmt'!B26 -> 박준형 | G4: ='Risk Mgmt'!C27 -> 0 | I4: ='Risk Mgmt'!C28 -> 홍예나 | K4: ='Risk Mgmt'!C29 -> 0
A5: Report Date | B5: =B4+3 -> 46342 | C5: =IF(WEEKDAY(B5)=1,"SUN",IF(WEEKDAY(B5)=2,"MON",IF(WEEKDAY(B5)=3,"TUE",IF(WEEKDAY(B5)=4,"WED",IF(WEEKDAY(B5)=5,"THU",IF(WEEKDAY(B5)=6,"FRI",IF(WEEKDAY(B5)=7,"SAT","-"))))))) -> MON
B6: ='06-Nov'!D34 -> 19908.944 | D6: Risk Mgmt Rules | E6: Loss-cut | F6: Profit-taking | G6: ETF | H6: Country | I6: Futures | J6: Options L | K6: Options S
A7: Cash Balace (KRW, before trades) | E7: ='06-Nov'!E7 -> 0.1 | F7: ='06-Nov'!F7 -> 0.15 | G7: ='06-Nov'!G7 -> 0.4 | H7: ='06-Nov'!H7 -> 0.8 | I7: ='06-Nov'!I7 -> 0.1 | J7: ='06-Nov'!J7 -> 0.1 | K7: ='06-Nov'!K7 -> 0.1
A9: Previous Positions | E9: 1 | F9: 2 | G9: 3 | H9: 4 | I9: 5 | J9: 6 | K9: 7 | L9: 8
A10: Long or Short | E10: ='06-Nov'!E38 -> 0 | F10: ='06-Nov'!F38 -> 0 | G10: ='06-Nov'!G38 -> 0 | H10: ='06-Nov'!H38 -> 0 | I10: ='06-Nov'!I38 -> 0 | J10: ='06-Nov'!J38 -> 0 | K10: ='06-Nov'!K38 -> 0 | L10: ='06-Nov'!L38 -> 0
A11: Product Name | E11: ='06-Nov'!E39 -> 0 | F11: ='06-Nov'!F39 -> 0 | G11: ='06-Nov'!G39 -> 0 | H11: ='06-Nov'!H39 -> 0 | I11: ='06-Nov'!I39 -> 0 | J11: ='06-Nov'!J39 -> 0 | K11: ='06-Nov'!K39 -> 0 | L11: ='06-Nov'!L39 -> 0
A12: Product Code | E12: ='06-Nov'!E40 -> 0 | F12: ='06-Nov'!F40 -> 0 | G12: ='06-Nov'!G40 -> 0 | H12: ='06-Nov'!H40 -> 0 | I12: ='06-Nov'!I40 -> 0 | J12: ='06-Nov'!J40 -> 0 | K12: ='06-Nov'!K40 -> 0 | L12: ='06-Nov'!L40 -> 0
A13: Product Type (ETF/Futures/Options) | E13: ='06-Nov'!E41 -> 0 | F13: ='06-Nov'!F41 -> 0 | G13: ='06-Nov'!G41 -> 0 | H13: ='06-Nov'!H41 -> 0 | I13: ='06-Nov'!I41 -> 0 | J13: ='06-Nov'!J41 -> 0 | K13: ='06-Nov'!K41 -> 0 | L13: ='06-Nov'!L41 -> 0
A14: Size (shares/contracts) | E14: ='06-Nov'!E42 -> 0 | F14: ='06-Nov'!F42 -> 0 | G14: ='06-Nov'!G42 -> 0 | H14: ='06-Nov'!H42 -> 0 | I14: ='06-Nov'!I42 -> 0 | J14: ='06-Nov'!J42 -> 0 | K14: ='06-Nov'!K42 -> 0 | L14: ='06-Nov'!L42 -> 0
A15: Multiple (Futures&Options) | E15: ='06-Nov'!E43 -> 0 | F15: ='06-Nov'!F43 -> 0 | G15: ='06-Nov'!G43 -> 0 | H15: ='06-Nov'!H43 -> 0 | I15: ='06-Nov'!I43 -> 0 | J15: ='06-Nov'!J43 -> 0 | K15: ='06-Nov'!K43 -> 0 | L15: ='06-Nov'!L43 -> 0
A18: New Trades | E18: 1 | F18: 2 | G18: 3 | H18: 4 | I18: 5 | J18: 6 | K18: 7 | L18: 8
A19: Buy or Sell
A20: Product Name
A21: Product Code
A22: Product Type (ETF/Futures/Options)
A23: Size (shares/contracts)
A24: Multiple (Futures&Options)
A25: ="New Price ("&TEXT($B$4,"yyyy-mm-dd")&")" -> New Price (2026-11-13)
A26: ="New FX (exchange rate) ("&TEXT($B$4,"yyyy-mm-dd")&")" -> New FX (exchange rate) (2026-11-13)
A27: ="New Converted Price ("&TEXT($B$4,"yyyy-mm-dd")&")" -> New Converted Price (2026-11-13) | E27: =E26*E25 -> 0 | F27: =F26*F25 -> 0 | G27: =G26*G25 -> 0 | H27: =H26*H25 -> 0 | I27: =I26*I25 -> 0 | J27: =J26*J25 -> 0 | K27: =K26*K25 -> 0 | L27: =L26*L25 -> 0
A28: Cashflow: Buy(-), Sell(+) | D28: =SUM(E28:AF28) -> 0 | E28: =IF(E19="Buy",-E23*E24*E27,IF(E19="Sell",+E23*E24*E27,"None")) -> None | F28: =IF(F19="Buy",-F23*F24*F27,IF(F19="Sell",+F23*F24*F27,"None")) -> None | G28: =IF(G19="Buy",-G23*G24*G27,IF(G19="Sell",+G23*G24*G27,"None")) -> None | H28: =IF(H19="Buy",-H23*H24*H27,IF(H19="Sell",+H23*H24*H27,"None")) -> None | I28: =IF(I19="Buy",-I23*I24*I27,IF(I19="Sell",+I23*I24*I27,"None")) -> None | J28: =IF(J19="Buy",-J23*J24*J27,IF(J19="Sell",+J23*J24*J27,"None")) -> None | K28: =IF(K19="Buy",-K23*K24*K27,IF(K19="Sell",+K23*K24*K27,"None")) -> None | L28: =IF(L19="Buy",-L23*L24*L27,IF(L19="Sell",+L23*L24*L27,"None")) -> None
D29: Net Cashflow
D31: =B6+D28 -> 19908.944
D32: New Cash Balance
A34: =IF(D31>0,"+"," ") -> + | B34: =IF(D31>0,0.035%,0.07%) -> 0.00035 | D34: =D31*(1+B34) -> 19915.912
D35: Nextweek Cash Balance
A37: Outstanding (New) Positions | E37: 1 | F37: 2 | G37: 3 | H37: 4 | I37: 5 | J37: 6 | K37: 7 | L37: 8
A38: Long or Short
A39: Product Name
A40: Product Code
A41: Product Type (ETF/Futures/Options)
A42: Size (shares/contracts)
A43: Multiple (Futures&Options)
A44: ="New Price ("&TEXT($B$4,"yyyy-mm-dd")&")" -> New Price (2026-11-13)
A45: ="New FX (exchange rate) ("&TEXT($B$4,"yyyy-mm-dd")&")" -> New FX (exchange rate) (2026-11-13)
A46: ="New Converted Price ("&TEXT($B$4,"yyyy-mm-dd")&")" -> New Converted Price (2026-11-13) | E46: =E45*E44 -> 0 | F46: =F45*F44 -> 0 | G46: =G45*G44 -> 0 | H46: =H45*H44 -> 0 | I46: =I45*I44 -> 0 | J46: =J45*J44 -> 0 | K46: =K45*K44 -> 0 | L46: =L45*L44 -> 0
A47: Market Values of ETFs | D47: =SUM(E47:AF47) -> 0 | E47: =IF(E38="Long",E42*E43*E46,IF(E38="Short",-E42*E43*E46,"None")) -> None | F47: =IF(F38="Long",F42*F43*F46,IF(F38="Short",-F42*F43*F46,"None")) -> None | G47: =IF(G38="Long",G42*G43*G46,IF(G38="Short",-G42*G43*G46,"None")) -> None | H47: =IF(H38="Long",H42*H43*H46,IF(H38="Short",-H42*H43*H46,"None")) -> None | I47: =IF(I38="Long",I42*I43*I46,IF(I38="Short",-I42*I43*I46,"None")) -> None | J47: =IF(J38="Long",J42*J43*J46,IF(J38="Short",-J42*J43*J46,"None")) -> None | K47: =IF(K38="Long",K42*K43*K46,IF(K38="Short",-K42*K43*K46,"None")) -> None | L47: =IF(L38="Long",L42*L43*L46,IF(L38="Short",-L42*L43*L46,"None")) -> None
...

Sheet 20-Nov
A1: ='Risk Mgmt'!A1 -> DBA4014 | C1: 6th week (final) Valuation | J1: as of | K1: =TEXT(B4,"YYYY-MM-DD") -> 2026-11-20
A3: Company | B3: ='30-Oct'!B3:B3 -> DBA4 | D3: CEO | E3: CRO | F3: CIO | G3: ='Risk Mgmt'!B27 -> Jacob | H3: Research | I3: ='Risk Mgmt'!B28 -> 장단비 | J3: COO | K3: ='Risk Mgmt'!B29 -> 채영찬
A4: Trade Date | B4: ='13-Nov'!B4+7 -> 46346 | C4: =IF(WEEKDAY(B4)=1,"SUN",IF(WEEKDAY(B4)=2,"MON",IF(WEEKDAY(B4)=3,"TUE",IF(WEEKDAY(B4)=4,"WED",IF(WEEKDAY(B4)=5,"THU",IF(WEEKDAY(B4)=6,"FRI",IF(WEEKDAY(B4)=7,"SAT","-"))))))) -> FRI | D4: ='Risk Mgmt'!B25 -> 김경수 | E4: ='Risk Mgmt'!B26 -> 박준형 | G4: ='Risk Mgmt'!C27 -> 0 | I4: ='Risk Mgmt'!C28 -> 홍예나 | K4: ='Risk Mgmt'!C29 -> 0
A5: Report Date | B5: =B4+3 -> 46349 | C5: =IF(WEEKDAY(B5)=1,"SUN",IF(WEEKDAY(B5)=2,"MON",IF(WEEKDAY(B5)=3,"TUE",IF(WEEKDAY(B5)=4,"WED",IF(WEEKDAY(B5)=5,"THU",IF(WEEKDAY(B5)=6,"FRI",IF(WEEKDAY(B5)=7,"SAT","-"))))))) -> MON
B6: ='13-Nov'!D34 -> 19915.912 | D6: Risk Mgmt Rules | E6: Loss-cut | F6: Profit-taking | G6: ETF | H6: Country | I6: Futures | J6: Options L | K6: Options S
A7: Cash Balace (KRW, before trades) | E7: ='13-Nov'!E7 -> 0.1 | F7: ='13-Nov'!F7 -> 0.15 | G7: ='13-Nov'!G7 -> 0.4 | H7: ='13-Nov'!H7 -> 0.8 | I7: ='13-Nov'!I7 -> 0.1 | J7: ='13-Nov'!J7 -> 0.1 | K7: ='13-Nov'!K7 -> 0.1
A9: Previous Positions | E9: 1 | F9: 2 | G9: 3 | H9: 4 | I9: 5 | J9: 6 | K9: 7 | L9: 8
A10: Long or Short | E10: ='13-Nov'!E38 -> 0 | F10: ='13-Nov'!F38 -> 0 | G10: ='13-Nov'!G38 -> 0 | H10: ='13-Nov'!H38 -> 0 | I10: ='13-Nov'!I38 -> 0 | J10: ='13-Nov'!J38 -> 0 | K10: ='13-Nov'!K38 -> 0 | L10: ='13-Nov'!L38 -> 0
A11: Product Name | E11: ='13-Nov'!E39 -> 0 | F11: ='13-Nov'!F39 -> 0 | G11: ='13-Nov'!G39 -> 0 | H11: ='13-Nov'!H39 -> 0 | I11: ='13-Nov'!I39 -> 0 | J11: ='13-Nov'!J39 -> 0 | K11: ='13-Nov'!K39 -> 0 | L11: ='13-Nov'!L39 -> 0
A12: Product Code | E12: ='13-Nov'!E40 -> 0 | F12: ='13-Nov'!F40 -> 0 | G12: ='13-Nov'!G40 -> 0 | H12: ='13-Nov'!H40 -> 0 | I12: ='13-Nov'!I40 -> 0 | J12: ='13-Nov'!J40 -> 0 | K12: ='13-Nov'!K40 -> 0 | L12: ='13-Nov'!L40 -> 0
A13: Product Type (ETF/Futures/Options) | E13: ='13-Nov'!E41 -> 0 | F13: ='13-Nov'!F41 -> 0 | G13: ='13-Nov'!G41 -> 0 | H13: ='13-Nov'!H41 -> 0 | I13: ='13-Nov'!I41 -> 0 | J13: ='13-Nov'!J41 -> 0 | K13: ='13-Nov'!K41 -> 0 | L13: ='13-Nov'!L41 -> 0
A14: Size (shares/contracts) | E14: ='13-Nov'!E42 -> 0 | F14: ='13-Nov'!F42 -> 0 | G14: ='13-Nov'!G42 -> 0 | H14: ='13-Nov'!H42 -> 0 | I14: ='13-Nov'!I42 -> 0 | J14: ='13-Nov'!J42 -> 0 | K14: ='13-Nov'!K42 -> 0 | L14: ='13-Nov'!L42 -> 0
A15: Multiple (Futures&Options) | E15: ='13-Nov'!E43 -> 0 | F15: ='13-Nov'!F43 -> 0 | G15: ='13-Nov'!G43 -> 0 | H15: ='13-Nov'!H43 -> 0 | I15: ='13-Nov'!I43 -> 0 | J15: ='13-Nov'!J43 -> 0 | K15: ='13-Nov'!K43 -> 0 | L15: ='13-Nov'!L43 -> 0
A18: Closing Trades | E18: 1 | F18: 2 | G18: 3 | H18: 4 | I18: 5 | J18: 6 | K18: 7 | L18: 8
A19: Buy or Sell
A20: Product Name
A21: Product Code
A22: Product Type (ETF/Futures/Options)
A23: Size (shares/contracts)
A24: Multiple (Futures&Options)
A25: ="New Price ("&TEXT($B$4,"yyyy-mm-dd")&")" -> New Price (2026-11-20)
A26: ="New FX (exchange rate) ("&TEXT($B$4,"yyyy-mm-dd")&")" -> New FX (exchange rate) (2026-11-20)
A27: ="New Converted Price ("&TEXT($B$4,"yyyy-mm-dd")&")" -> New Converted Price (2026-11-20) | E27: =E26*E25 -> 0 | F27: =F26*F25 -> 0 | G27: =G26*G25 -> 0 | H27: =H26*H25 -> 0 | I27: =I26*I25 -> 0 | J27: =J26*J25 -> 0 | K27: =K26*K25 -> 0 | L27: =L26*L25 -> 0
A28: Cashflow: Buy(-), Sell(+) | D28: =SUM(E28:AF28) -> 0 | E28: =IF(E19="Buy",-E23*E24*E27,IF(E19="Sell",+E23*E24*E27,"None")) -> None | F28: =IF(F19="Buy",-F23*F24*F27,IF(F19="Sell",+F23*F24*F27,"None")) -> None | G28: =IF(G19="Buy",-G23*G24*G27,IF(G19="Sell",+G23*G24*G27,"None")) -> None | H28: =IF(H19="Buy",-H23*H24*H27,IF(H19="Sell",+H23*H24*H27,"None")) -> None | I28: =IF(I19="Buy",-I23*I24*I27,IF(I19="Sell",+I23*I24*I27,"None")) -> None | J28: =IF(J19="Buy",-J23*J24*J27,IF(J19="Sell",+J23*J24*J27,"None")) -> None | K28: =IF(K19="Buy",-K23*K24*K27,IF(K19="Sell",+K23*K24*K27,"None")) -> None | L28: =IF(L19="Buy",-L23*L24*L27,IF(L19="Sell",+L23*L24*L27,"None")) -> None
D29: Net Cashflow
D31: =B6+D28 -> 19915.912
D32: New Cash Balance
F33: =D31/'09-Oct'!A6-1 -> -0.99999801
F34: Rate of Return from inception

Sheet PeerEV
B2: DBA ? | D2: Person who evaluates:
D3: ='Risk Mgmt'!B25 -> 김경수 | E3: ='Risk Mgmt'!B26 -> 박준형 | F3: ='Risk Mgmt'!B27 -> Jacob | G3: ='Risk Mgmt'!B28 -> 장단비 | H3: ='Risk Mgmt'!B29 -> 채영찬 | I3: ='Risk Mgmt'!C28 -> 홍예나 | J3: ='Risk Mgmt'!C29 -> 0
B4: Team members to be evaluated | C4: ='Risk Mgmt'!B25 -> 김경수
C5: ='Risk Mgmt'!B26 -> 박준형
C6: ='Risk Mgmt'!B27 -> Jacob
C7: ='Risk Mgmt'!B28 -> 장단비
C8: ='Risk Mgmt'!B29 -> 채영찬
C9: ='Risk Mgmt'!C28 -> 홍예나
C10: ='Risk Mgmt'!C29 -> 0
B16: [SAMPLE] | C16: *** Peer Evaluation Matrix: 5/4/3/2/1/0 of Student3
E17: Person who evaluates: | I17: Student3
C18: [SAMPLE] | D18: ê | E18: Student1 | F18: Student2 | G18: Student3 | H18: Student4 | I18: Student5 | J18: Student6 | K18: Student7
C19: Team members to be evaluated by Student3 | D19: Student1 | G19: 5
D20: Student2 | G20: 2
D21: Student3 | G21: 3
D22: Student4 | G22: 4
D23: Student5 | G23: 1
D24: Student6 | G24: 2
D25: Student7 | G25: 0
H27: <-- Self-evaluation
